Workbook
Name A1VerVal: Drops!$B$27
Name BusInfoArray: 'Business Information'!$A$4:$E$38
Name CompanyHashSIG: Drops!$B$36
Name CompanyName: Drops!$B$34
Name CompanyNameFlag: Drops!$B$35
Name CurrentVersionSIG: Drops!$B$25
Name FullResponses: Full!$A$2:$M$1026
Name JumpArray: Drops!$F$26:$F$44
Name JumpSelection: Drops!$F$45
Name OutputArray: Drops!$M$2:$U$5758
Name ServiceSelection: Drops!$M$2:$N$5758

Sheet Copyright
B2: 2021 SHARED ASSESSMENTS STANDARDIZED INFORMATION GATHERING (SIG) QUESTIONNAIRE
B3: ="Version: "&CurrentVersionSIG&" - Licensed to: "&CompanyName -> Version: 2021.02 - Licensed to: Seismic Software
B4: The SIG Questionnaire Tools are a comprehensive questionnaire management interface that lets you build, customize, store and automatically analyze SIG questionnaires and their associated evidence requirements all in one place. It is built on a holistic set of industry best practices for gathering and assessing 18 critical control domains including information technology, cybersecurity, privacy, resiliency and compliance risks and their corresponding controls. Service providers can also use SIG Questionnaires to reduce assessment fatigue by proactively supplying their own SIGs to Outsourcers.
B5: © 2020, 2021 The Santa Fe Group, Shared Assessments Program. All rights reserved.
B6: Documents created under the Shared Assessments Program may be downloaded from the official Shared Assessments Program website at SharedAssessments.org.
B7: While retaining copyrights, the Shared Assessments Program makes specific documents available via license for assessments and other uses. Individuals and organizations should review the terms of use prior to downloading, copying, using or modifying Shared Assessment Program documents.
B8: This notice must be included on any copy of the Shared Assessments Program documents, excluding Assessors' or consultants' reports.
B9: The Shared Assessments Program is administered by The Santa Fe Group at Santa-Fe-Group.com.
B10: Please refer to the support documentation provided on how to use this workbook. If you have additional questions or issues, please go to SharedAssessments.org/tools-support/.
B11: To learn more about our education offerings or sign up for one of our workshops please go to SharedAssessments.org.
B12: If you are interested in learning more about the Shared Assessments Program and would like us to contact you, email us at info@SharedAssessments.org.
B13: Terms of Use
B14: 2021 SHARED ASSESSMENTS STANDARDIZED INFORMATION GATHERING (SIG) QUESTIONNAIRE TOOLS (2021 SIG)
B15: The Shared Assessments Program ("Program") maintains, promotes and facilitates the use of the Standardized Information Gathering ("SIG") questionnaire documents and other Program resource documents.
... B22: THE SHARED ASSESSMENTS PROGRAM DOCUMENTS ARE PROVIDED "AS IS" AND ANY EXPRESSED OR IMPLIED WARRANTIES, INCLUDING, BUT NOT LIMITED TO, THE IMPLIED WARRANTIES OF MERCHANTABILITY AND FITNESS FOR A PARTICULAR PURPOSE, ARE DISCLAIMED. IN NO EVENT SHALL THE SANTA FE GROUP, OR THE SHARED ASSESSMENTS PROGRAM, ITS SPONSORS OR PROGRAM MEMBERS BE LIABLE FOR ANY DIRECT, INDIRECT, INCIDENTAL, SPECIAL, EXEMPLARY, OR CONSEQUENTIAL DAMAGES (INCLUDING, BUT NOT LIMITED TO, PROCUREMENT OF SUBSTITUTE GOODS OR SERVICES; LOSS OF USE, DATA, OR PROFITS; OR BUSINESS INTERRUPTION) HOWEVER CAUSED AND ON ANY THEORY OF LIABILITY, WHETHER IN CONTRACT, STRICT LIABILITY, OR TORT (INCLUDING NEGLIGENCE OR OTHERWISE) ARISING IN ANY WAY OUT OF THE USE OF THE SHARED ASSESSMENTS PROGRAM DOCUMENTS, EVEN IF ADVISED OF THE POSSIBILITY OF SUCH DAMAGE.

Sheet Instructions
B2: 2021 SHARED ASSESSMENTS STANDARDIZED INFORMATION GATHERING (SIG) QUESTIONNAIRE
B3: ="Version: "&CurrentVersionSIG&" Licensed to: "&CompanyName -> Version: 2021.02 Licensed to: Seismic Software
B4: ASSESSEE INSTRUCTIONS FOR SIG QUESTIONNAIRE COMPLETION: | D4: ISSUER/OUTSOURCER ADDITIONAL INFORMATION
B5: Before You Start: Review the instructions provided by your Issuer/Outsourcer on how to answer the SIG. Issuer/Outsourcer should provide you with the scope of services for which to provide responses. The SIG is complex. If you did not receive instructions from your Issuer/Outsourcer it is recommended that you contact them before you start and seek guidance on how to proceed with the SIG to meet their needs.
B6: Don't be overwhelmed by the volume of questions. Some are filtering questions to remove out of scope services or have a question hierarchy to reduce the need to complete items that are NA. Primary or ‘parent’ questions, indicated in bold, are followed by numbered sub or ‘child’ questions. If a parent question is answered Yes, child questions will display. There can be up to four generations of questions below a parent question.
B7: NOTE: To display all of the questions (parent, child, grandchild, etc.) disable macros when opening the file or select Disable from the Tab Automation dropdown on each risk domain tab.
B8: Steps for each SIG Worksheet:
B9: 1) Complete the Business Information tab: Open the tab and complete all of the grey fields. It is recommended that you provide as much detail as possible in your responses.
B10: 2) Review and Complete the Documentation tab: Open the Documentation tab. Review the list of documents and compile all of the appropriate corporate policies and processes as listed on this tab. List the document’s name in the gray field to correspond to the appropriate document list. This will allow the Outsourcer to identify the documents provided along with the completed SIG. Compile the documentation requested on the Documentation tab and update the tab with the documents provided.
B11: 3) Answer the Questions in each Risk Domain tab:
B12: • The background color will change depending on the response provided.
B13: • If Excel macros are enabled, then Child questions will either be displayed if the response is Yes or hidden if the response is No or N/A.
B14: • If the question is a Parent question and the response is No or N/ A, then the background will change to the associated color for all Child and Grandchild questions of that Parent.
B15: • When selecting an N/A response, commentary must be entered in the Additional Information field explaining why that question is not applicable.
B16: • The progress bar at the top of the page shows the percentage of questions completed for a given tab.
... B18: 5) Sending the Completed SIG: Once all of the answers have been entered, send the completed SIG and all policy/process documents compiled in Step 1-3 to the Outsourcer according to the instructions you have been provided.
B19: Question Numbering | D19: Glossary:
B20: There may be gaps in the question numbering depending on how the Issuer/Outsourcer scoped the SIG. | D20: For definitions of terms within this document, please refer to the following link: https://sharedassessments.org/glossary

Sheet Dashboard
B2: Dashboard | G2: 1
B3: The Dashboard provides you with a quick and easy reference to determine the percentage of completion for the required sections of the SIG. As questions are answered, either directly or by being pre-filled, the Dashboard will track the completion percentage of each section. | G3: 1
B4: Tabs | C4: % Comp | D4: Please wait for the SIG to update... | E4: Response Cell Background Color Coding (All tabs) | F4: Resp | G4: 1
B5: Copyright | C5: N/A | E5: Response Required (cells with a gray background are editable) | G5: 1
B6: Instructions | C6: N/A | E6: Yes Response | F6: Yes | G6: 1
B7: Business Information | C7: ='Business Information'!C2 -> 1 | E7: No Response | F7: No | G7: 1
B8: Documentation | C8: N/A | E8: N/A Response | F8: N/A | G8: 1
B9: A. Risk Assessment and Treatment | C9: =Drops!H3 | G9: =IF(Drops!I3=TRUE,1,0) -> 0
B10: B. Security Policy | C10: =Drops!H4 | G10: =IF(Drops!I4=TRUE,1,0) -> 0
B11: C. Organizational Security | C11: =Drops!H5 | D11: Response Type | G11: =IF(Drops!I5=TRUE,1,0) -> 0
B12: D. Asset and Information Management | C12: =Drops!H6 | D12: Binary | G12: =IF(Drops!I6=TRUE,1,0) -> 0
B13: E. Human Resource Security | C13: =Drops!H7 | G13: =IF(Drops!I7=TRUE,1,0) -> 0
B14: F. Physical and Environmental Security | C14: =Drops!H8 | G14: =IF(Drops!I8=TRUE,1,0) -> 0
B15: G. IT Operations Management | C15: =Drops!H9 | G15: =IF(Drops!I9=TRUE,1,0) -> 0
B16: H. Access Control | C16: =Drops!H10 | G16: =IF(Drops!I10=TRUE,1,0) -> 0
B17: I. Application Security | C17: =Drops!H11 | G17: =IF(Drops!I11=TRUE,1,0) -> 0
B18: J. Incident Event and Communications Management | C18: =Drops!H12 | G18: =IF(Drops!I12=TRUE,1,0) -> 0
B19: K. Business Resiliency | C19: =Drops!H13 | G19: =IF(Drops!I13=TRUE,1,0) -> 0
B20: L. Compliance | C20: =Drops!H14 | G20: =IF(Drops!I14=TRUE,1,0) -> 0
B21: M. End User Device Security | C21: =Drops!H15 | G21: =IF(Drops!I15=TRUE,1,0) -> 0
B22: N. Network Security | C22: =Drops!H16 | G22: =IF(Drops!I16=TRUE,1,0) -> 0
B23: P. Privacy | C23: =Drops!H17 | G23: =IF(Drops!I17=TRUE,1,0) -> 0
B24: T. Threat Management | C24: =Drops!H18 | G24: =IF(Drops!I18=TRUE,1,0) -> 0
... B28: SIG 2021 | C28: =Drops!H22 -> 1 | G28: =IF(Drops!I22=TRUE,1,0) -> 1
B29: Glossary | C29: N/A | G29: 1
B30: Formula Notes | C30: N/A | G30: 1
B31: Full | C31: N/A | G31: =IF(Drops!I23=TRUE,1,0) -> 1
B32: SIG Total | C32: =Drops!H24 -> 1 | G32: 1

Sheet Business Information
A1: Serial No | B1: Business Information | D1: Count | E1: Resp
B2: Progress: | C2: =IF(D3=0,"0%",D3/D2) -> 1 | D2: =COUNTA(D4:D61) -> 47
B3: Question/Request | D3: =COUNTIF(D4:D61,1) -> 47
A4: 2891 | B4: Assessee Name | C4: Information Security | D4: =COUNTA(C4) -> 1 | E4: =IF(C4="Yes",1,IF(C4="No",2,IF(C4="N/A",3,0))) -> 0
A5: 2892 | B5: Assessee Job Title | C5: Sr. Director of Information Security | D5: =COUNTA(C5) -> 1 | E5: =IF(C5="Yes",1,IF(C5="No",2,IF(C5="N/A",3,0))) -> 0
A6: 2893 | B6: Assessee Contact Information | C6: security@seismic.com | D6: =COUNTA(C6) -> 1 | E6: =IF(C6="Yes",1,IF(C6="No",2,IF(C6="N/A",3,0))) -> 0
A7: 4616 | B7: Names and titles/functions of individuals who contributed to this questionnaire | C7: Same as above | D7: =COUNTA(C7) -> 1 | E7: =IF(C7="Yes",1,IF(C7="No",2,IF(C7="N/A",3,0))) -> 0
A8: 2894 | B8: Date of Response | C8: 44454 | D8: =COUNTA(C8) -> 1 | E8: =IF(C8="Yes",1,IF(C8="No",2,IF(C8="N/A",3,0))) -> 0
B9: Company Profile | E9: =IF(C9="Yes",1,IF(C9="No",2,IF(C9="N/A",3,0))) -> 0
A10: 2896 | B10: Name of the holding or parent company | C10: Seismic Software | D10: =COUNTA(C10) -> 1 | E10: =IF(C10="Yes",1,IF(C10="No",2,IF(C10="N/A",3,0))) -> 0
A11: 2897 | B11: Company/business name | C11: Lessonly by Seismic | D11: =COUNTA(C11) -> 1 | E11: =IF(C11="Yes",1,IF(C11="No",2,IF(C11="N/A",3,0))) -> 0
A12: 2898 | B12: Publicly or privately held company | C12: Privately held | D12: =COUNTA(C12) -> 1 | E12: =IF(C12="Yes",1,IF(C12="No",2,IF(C12="N/A",3,0))) -> 0
A13: 2899 | B13: If public, what is the name of the Exchange | D13: =IF(C12="Privately held",1,COUNTA(C13)) -> 1 | E13: =IF(C13="Yes",1,IF(C13="No",2,IF(C13="N/A",3,0))) -> 0
A14: 2900 | B14: If public, what is the trading symbol | D14: =IF(C12="Privately held",1,COUNTA(C14)) -> 1 | E14: =IF(C14="Yes",1,IF(C14="No",2,IF(C14="N/A",3,0))) -> 0
A15: 2901 | B15: Type of legal entity and state of incorporation | C15: C-Corp, Delaware | D15: =COUNTA(C15) -> 1 | E15: =IF(C15="Yes",1,IF(C15="No",2,IF(C15="N/A",3,0))) -> 0
A16: 2902 | B16: How long has the company been in business | C16: Since 2014 | D16: =COUNTA(C16) -> 1 | E16: =IF(C16="Yes",1,IF(C16="No",2,IF(C16="N/A",3,0))) -> 0
A17: 2903 | B17: Are there any material claims or judgments against the company | C17: No | D17: =COUNTA(C17) -> 1 | E17: =IF(C17="Yes",1,IF(C17="No",2,IF(C17="N/A",3,0))) -> 2
A18: 2904 | B18: If yes, describe the impact it may have on the services in scope of this document | D18: =IF(C17="No",1,COUNTA(C18)) -> 1 | E18: =IF(C18="Yes",1,IF(C18="No",2,IF(C18="N/A",3,0))) -> 0
A19: 4000 | B19: Has your company suffered a data loss or security breach within the last 3 years | C19: No | D19: =COUNTA(C19) -> 1 | E19: =IF(C19="Yes",1,IF(C19="No",2,IF(C19="N/A",3,0))) -> 2
A20: 4001 | B20: If yes, please describe the loss or breach | D20: =IF(C19="No",1,COUNTA(C20)) -> 1 | E20: =IF(C20="Yes",1,IF(C20="No",2,IF(C20="N/A",3,0))) -> 0
A21: 4002 | B21: Has any of your Third Party Vendors suffered a data loss or security breach within the last 3 years | C21: No | D21: =COUNTA(C21) -> 1 | E21: =IF(C21="Yes",1,IF(C21="No",2,IF(C21="N/A",3,0))) -> 2
A22: 4003 | B22: If yes, please describe the loss or breach | C22: Not to our knowledge | D22: =IF(C21="No",1,COUNTA(C22)) -> 1 | E22: =IF(C22="Yes",1,IF(C22="No",2,IF(C22="N/A",3,0))) -> 0
B23: Scope | E23: =IF(C23="Yes",1,IF(C23="No",2,IF(C23="N/A",3,0))) -> 0
A24: 2911 | B24: Are the answers in this questionnaire for only one facility or geographic location If yes, provide description of physical location (address, city, state, country) | C24: No | D24: =COUNTA(C24) -> 1 | E24: =IF(C24="Yes",1,IF(C24="No",2,IF(C24="N/A",3,0))) -> 2
A25: 2912 | B25: Backup site physical address | C25: AWS East-1 | D25: =COUNTA(C25) -> 1 | E25: =IF(C25="Yes",1,IF(C25="No",2,IF(C25="N/A",3,0))) -> 0
A26: 2913 | B26: Any additional locations where Scoped Systems and Data are stored | C26: No | D26: =COUNTA(C26) -> 1 | E26: =IF(C26="Yes",1,IF(C26="No",2,IF(C26="N/A",3,0))) -> 2
A27: 2914 | B27: If yes, provide each location (address, city, state, country) | D27: =IF(C26="No",1,COUNTA(C27)) -> 1 | E27: =IF(C27="Yes",1,IF(C27="No",2,IF(C27="N/A",3,0))) -> 0
A28: 2973 | B28: Are the answers to this questionnaire for only one specific type of service If yes, describe the service | C28: SaaS | D28: =COUNTA(C28) -> 1 | E28: =IF(C28="Yes",1,IF(C28="No",2,IF(C28="N/A",3,0))) -> 0
A29: 4617 | B29: Are software applications provided | C29: Yes | D29: =COUNTA(C29) -> 1 | E29: =IF(C29="Yes",1,IF(C29="No",2,IF(C29="N/A",3,0))) -> 1
A30: 3992 | B30: List the applications provided that are in scope | C30: Lessonly by Seismic | D30: =IF($C$29="No",1,COUNTA(C30)) -> 1 | E30: =IF(C30="Yes",1,IF(C30="No",2,IF(C30="N/A",3,0))) -> 0
A31: 3993 | B31: Identify the applications which are covered by the secure software development lifecycle | C31: Lessonly by Seismic | D31: =IF($C$29="No",1,COUNTA(C31)) -> 1 | E31: =IF(C31="Yes",1,IF(C31="No",2,IF(C31="N/A",3,0))) -> 0
A32: 3994 | B32: What type of software is being provided, select all that apply from the list below: | E32: =IF(C32="Yes",1,IF(C32="No",2,IF(C32="N/A",3,0))) -> 0
A33: 3995 | B33: Commercial Off-The-Shelf (COTS) | C33: No | D33: =IF($C$29="No",1,COUNTA(C33)) -> 1 | E33: =IF(C33="Yes",1,IF(C33="No",2,IF(C33="N/A",3,0))) -> 2
A34: 3996 | B34: Custom Developed | C34: No | D34: =IF($C$29="No",1,COUNTA(C34)) -> 1 | E34: =IF(C34="Yes",1,IF(C34="No",2,IF(C34="N/A",3,0))) -> 2
A35: 3997 | B35: Cloud | C35: Yes | D35: =IF($C$29="No",1,COUNTA(C35)) -> 1 | E35: =IF(C35="Yes",1,IF(C35="No",2,IF(C35="N/A",3,0))) -> 1
A36: 3998 | B36: Mobile | C36: No | D36: =IF($C$29="No",1,COUNTA(C36)) -> 1 | E36: =IF(C36="Yes",1,IF(C36="No",2,IF(C36="N/A",3,0))) -> 2
A37: 4004 | B37: Open Source Software | C37: No | D37: =IF($C$29="No",1,COUNTA(C37)) -> 1 | E37: =IF(C37="Yes",1,IF(C37="No",2,IF(C37="N/A",3,0))) -> 2
A38: 3999 | B38: Other | C38: No | D38: =IF($C$29="No",1,COUNTA(C38)) -> 1 | E38: =IF(C38="Yes",1,IF(C38="No",2,IF(C38="N/A",3,0))) -> 2
A39: 4410 | B39: Does your company require approval prior to submitting the responses and documentation associated with this document | C39: No | D39: =COUNTA(C39) -> 1
A40: 4411 | B40: If yes, describe your approval process and the individual who approves the submission | D40: =IF($C$39="No",1,COUNTA(C40)) -> 1
...

Sheet Documentation
A1: Serial No | B1: Documentation Use this section to request any specific documentation you want the Assessee to provide along with the SIG
A2: SN | B2: Document Request | C2: Domain | D2: SCA Reference | E2: Document Access | F2: Documentation Description
A3: 5660 | B3: Documentation that defines the Enterprise Risk Management program requirements (i.e., Enterprise risk governance plan, policies and procedures) | C3: A. Risk Assessment & Treatment | D3: A.1
A4: 5661 | B4: Documentation that defines the organization's risk assessment lifecycle. Inventory/register of applicable risks and controls included in the risk management program | C4: A. Risk Assessment & Treatment | D4: A.2
A5: 5662 | B5: Documentation that defines oversight functions and procedures accountable for compliance with legal, regulatory, and standards obligations | C5: A. Risk Assessment & Treatment | D5: A.3
A6: 5663 | B6: Documentation that defines the IT risk assessment process requirements for systems and critical business processes, including a list of critical business processes related to the services provided | C6: A. Risk Assessment & Treatment | D6: A.4
A7: 5664 | B7: Documentation that defines the organization's third party risk management program and assessment requirements e.g., policies, standards, procedures. Documentation and evidence of the structure and maintenance of the organization's third party inventory and vendor classification | C7: A. Risk Assessment & Treatment | D7: A.5
A8: 5665 | B8: Documentation that describes the organization's process for addressing security contract clauses within service provider agreements and provides evidence that the organization's required security requirements (e.g., standard provisions, model contracts, contract term database) have been included in its vendor contracting process. Documentation that defines the organization's guidelines and process for management and approval of exception handling for required contract terms | C8: A. Risk Assessment & Treatment | D8: A.6
A9: 5666 | B9: Documentation that defines the requirements for subcontractor selection and management | C9: A. Risk Assessment & Treatment | D9: A.7
A10: 5667 | B10: A list of the critical subcontractors and evidence of the execution of the standard contract provisions, master services agreements in place for identified critical subcontractor relationships that are required for the delivery of the services | C10: A. Risk Assessment & Treatment | D10: A.8
A11: 5668 | B11: Documentation that defines the requirements for the assessment process that is in place to manage information security of its subcontractors | C11: A. Risk Assessment & Treatment | D11: A.9
A12: 5669 | B12: A copy of the formal criteria and methodology used to identify the inherent risk associated to a subcontractor | C12: A. Risk Assessment & Treatment | D12: A.10
A13: 5670 | B13: Documentation that reflects the logging, tracking and risk rating of subcontractor issues | C13: A. Risk Assessment & Treatment | D13: A.11
A14: 2922 | B14: Documentation of the organization's information security policies | C14: B. Security Policy | D14: B.1
... A136: 5779 | B136: Documentation that defines the CSP's process for validating secure configurations and documentation of its operational practices that are being applied to its virtual host systems and hypervisors, pre and postproduction, including a sample of the applicable system log report | C136: V. Cloud Hosting | D136: V.3

Sheet SIG 2021
A1: =A1VerVal -> 18 | B1: SIG 2021 | E1: =" Scoped As: "&Drops!A24 -> Scoped As: SIG Core 2021 | H1: Jump To: | M1: Tot | N1: Ans | O1: aa023ad7efc04973ff784e5fb415cc33 | W1: Yes | X1: No | Y1: N/A | AA1: Enable | AB1: Disable | AM1: SME SIG
B2: Licensed to: Seismic Software | D2: Progress: | E2: =IF(N2=0,"0%",N2/M2) -> 1 | H2: Tab Automation: | I2: Enable | M2: =COUNTIF(L:L,">0") -> 1025 | N2: =COUNTIF(S:S,">0") -> 1025 | W2: 1 | X2: 2 | Y2: 3 | Z2: 4 | AA2: 5 | AB2: N/A
B3: Questionnaire Instructions: - For each question choose either Yes, No or N/A from the drop-down menu provided. If N/A is chosen, an explanation is recommended. Use the Additional Information field in column E to provide an explanation. - To display the entire contents of the tab, select the word "Disable" in the Tab Automation field at the top of the page. - There may be gaps in the question number sequence depending on how the outsourcer generated the SIG. MODIFICATION OF THIS DOCUMENT IS A VIOLATION OF THE COPYRIGHT AND MAY RESULT IN FINANCIAL PENALTY FOR YOU OR YOUR SERVICE PROVIDER | L3: Q Depth | M3: Scoping Level | N3: Maturity N/A | P3: Answer Calc | Q3: Jump Domain | R3: Jump Row | S3: Resp Calc | T3: Family Delta | U3: Tab | V3: L1 Calc | W3: L2 Calc | X3: L3 Calc | Y3: L4 Calc | Z3: L5 Calc | AA3: Child Filter | AB3: Bold Ques Text | AC3: L1 Res Carry | AD3: L2 Res Carry | AE3: L3 Res Carry | AF3: L4 Res Carry | AG3: L5 Res Carry | AH3: L1 Filter Calc | AI3: L2 Filter Calc | AJ3: L3 Filter Calc | AK3: L4 Filter Calc | AL3: L5 Filter Calc | AM3: This SIG is intended for internal use only. Do not distribute outside of the organization.
A4: Serial No | B4: Ques Num | C4: Question/Request | D4: Response | E4: Additional Information | F4: Maturity | G4: Category | H4: Sub-category | I4: SCA Reference | J4: ISO 27002:2013 Relevance | U4: =U5 -> A | V4: 1 | W4: 2 | X4: 3 | Y4: 4 | Z4: 5 | AC4: 1 | AD4: 2 | AE4: 3 | AF4: 4 | AG4: 5 | AH4: 1 | AI4: 2 | AJ4: 3 | AK4: 4 | AL4: 5 | AM4: Subject Matter Expert Name | AN4: Subject Matter Expert Notes | AO4: Optional Score
A5: 5643 | B5: A.1 | C5: Is there a formalized risk governance plan that defines the Enterprise Risk Management program requirements? | D5: Yes | E5: Seismic has an established Risk Governance Program based off ISO 27005 controls. The program is run by Seismic's internal Information Security team. Seismic performs Enterprise Risk Assessment at least annually and communicate risk findings to executive management. Where risks are identified, appropriate controls are established to remove or reduce the risk to an acceptable level. | G5: Enterprise Risk Management | H5: Risk Governance Plan | I5: A.1 Enterprise Risk Governance | J5: An organization's enterprise risk governance program should include a formal program that documents the organization's assets and threats and evaluates associated risks. | L5: 1 | M5: 2 | P5: =IF($L5="","",IF($D5="Yes",1,IF($D5="No",2,IF($D5="N/A",3,0)))) -> 1 | Q5: =IF(AND(Drops!$D$45>1,OR(U5<>U4,AND(ROW()=5,U4=U5))),VLOOKUP(U5,Drops!$D$26:$E$44,2,FALSE),"") -> A. Risk Management | R5: =IF(Q5<>"",ROW(),"") -> 5 | S5: =OFFSET(AC5,,L5-1) -> 1 | T5: =IF(OR(V5<>V4,U5<>U4,AND(V5<>V4,W5<>W4),AND(V5<>V4,W5<>W4,X5<>X4),AND(V5<>V4,W5<>W4,X5<>X4,Y5<>Y4),AND(V5<>V4,W5<>W4,X5<>X4,Y5<>Y4,Z5<>Z4),L5-L4>1),1,0) -> 0 | U5: A | V5: 1 | W5: 0 | X5: 0 | Y5: 0 | Z5: 0 | AA5: =IF(ROW()=5,1,IF(OR(AH5=1,P5>0,T5=1),1,IF(OR(AND(AH5=2,AI5=1),AND(AI5=2,AJ5=1),AND(AJ5=2,AK5=1),AND(AK5=2,AL5=1)),1,0))) -> 1 | AB5: =IF(L6>L5,1,0) -> 1 | AC5: =IF(ROW()=5,P5,IF(AND($P5>1,AC$4=$L5),$P5,IF(AND($U5=$U4,V5=V4),AC4,IF(AND($L5=AC$4,P5=1),P5,0)))) -> 1 | AD5: =IF(AC5>1,AC5,IF(AND($P5>1,AD$4=$L5),$P5,IF(AND($U5=$U4,W5=W4),AD4,IF(AND($L5=AD$4,P5=1),P5,0)))) -> 0 | AE5: =IF(AD5>1,AD5,IF(AND($P5>1,AE$4=$L5),$P5,IF(AND($U5=$U4,X5=X4),AE4,IF(AND($L5=AE$4,P5=1),P5,0)))) -> 0 | AF5: =IF(AE5>1,AE5,IF(AND($P5>1,AF$4=$L5),$P5,IF(AND($U5=$U4,Y5=Y4),AF4,IF(AND($L5=AF$4,P5=1),P5,0)))) -> 0 | AG5: =IF(AF5>1,AF5,IF(AND($P5>1,AG$4=$L5),$P5,IF(AND($U5=$U4,Z5=Z4),AG4,IF(AND($L5=AG$4,P5=1),P5,0)))) -> 0 | AH5: =IF(AND($P5=1,$L5=AH$4),2,IF(AND($L5<>AH$4,AH4=2),AH4,IF($L5<>AH$4,0,1))) -> 2 | AI5: =IF(OR(ROW()=5,$U4<>$U5),0,IF(AND($P5=1,$L5=AI$4),2,IF(AND($L5<>AI$4,AI4=2),AI4,IF($L5<>AI$4,0,1)))) -> 0 | AJ5: =IF(OR(ROW()=5,$U4<>$U5),0,IF(AND($P5=1,$L5=AJ$4),2,IF(AND($L5<>AJ$4,AJ4=2),AJ4,IF($L5<>AJ$4,0,1)))) -> 0 | AK5: =IF(OR(ROW()=5,$U4<>$U5),0,IF(AND($P5=1,$L5=AK$4),2,IF(AND($L5<>AK$4,AK4=2),AK4,IF($L5<>AK$4,0,1)))) -> 0 | AL5: =IF(OR(ROW()=5,$U4<>$U5),0,IF(AND($P5=1,$L5=AL$4),2,IF(AND($L5<>AL$4,AL4=2),AL4,IF($L5<>AL$4,0,1)))) -> 0
A6: 2325 | B6: A.1.1 | C6: Does the risk governance plan include risk management policies, procedures, and internal controls? | D6: Yes | G6: Enterprise Risk Management | H6: Risk Governance Plan | I6: A.1 Enterprise Risk Governance | L6: 2 | M6: 2 | P6: =IF($L6="","",IF($D6="Yes",1,IF($D6="No",2,IF($D6="N/A",3,0)))) -> 1 | Q6: =IF(AND(Drops!$D$45>1,OR(U6<>U5,AND(ROW()=5,U5=U6))),VLOOKUP(U6,Drops!$D$26:$E$44,2,FALSE),"") | R6: =IF(Q6<>"",ROW(),"") | S6: =OFFSET(AC6,,L6-1) -> 1 | T6: =IF(OR(V6<>V5,U6<>U5,AND(V6<>V5,W6<>W5),AND(V6<>V5,W6<>W5,X6<>X5),AND(V6<>V5,W6<>W5,X6<>X5,Y6<>Y5),AND(V6<>V5,W6<>W5,X6<>X5,Y6<>Y5,Z6<>Z5),L6-L5>1),1,0) -> 0 | U6: A | V6: 1 | W6: 1 | X6: 0 | Y6: 0 | Z6: 0 | AA6: =IF(ROW()=5,1,IF(OR(AH6=1,P6>0,T6=1),1,IF(OR(AND(AH6=2,AI6=1),AND(AI6=2,AJ6=1),AND(AJ6=2,AK6=1),AND(AK6=2,AL6=1)),1,0))) -> 1 | AB6: =IF(L7>L6,1,0) -> 0 | AC6: =IF(ROW()=5,P6,IF(AND($P6>1,AC$4=$L6),$P6,IF(AND($U6=$U5,V6=V5),AC5,IF(AND($L6=AC$4,P6=1),P6,0)))) -> 1 | AD6: =IF(AC6>1,AC6,IF(AND($P6>1,AD$4=$L6),$P6,IF(AND($U6=$U5,W6=W5),AD5,IF(AND($L6=AD$4,P6=1),P6,0)))) -> 1 | AE6: =IF(AD6>1,AD6,IF(AND($P6>1,AE$4=$L6),$P6,IF(AND($U6=$U5,X6=X5),AE5,IF(AND($L6=AE$4,P6=1),P6,0)))) -> 0 | AF6: =IF(AE6>1,AE6,IF(AND($P6>1,AF$4=$L6),$P6,IF(AND($U6=$U5,Y6=Y5),AF5,IF(AND($L6=AF$4,P6=1),P6,0)))) -> 0 | AG6: =IF(AF6>1,AF6,IF(AND($P6>1,AG$4=$L6),$P6,IF(AND($U6=$U5,Z6=Z5),AG5,IF(AND($L6=AG$4,P6=1),P6,0)))) -> 0 | AH6: =IF(AND($P6=1,$L6=AH$4),2,IF(AND($L6<>AH$4,AH5=2),AH5,IF($L6<>AH$4,0,1))) -> 2 | AI6: =IF(OR(ROW()=5,$U5<>$U6),0,IF(AND($P6=1,$L6=AI$4),2,IF(AND($L6<>AI$4,AI5=2),AI5,IF($L6<>AI$4,0,1)))) -> 2 | AJ6: =IF(OR(ROW()=5,$U5<>$U6),0,IF(AND($P6=1,$L6=AJ$4),2,IF(AND($L6<>AJ$4,AJ5=2),AJ5,IF($L6<>AJ$4,0,1)))) -> 0 | AK6: =IF(OR(ROW()=5,$U5<>$U6),0,IF(AND($P6=1,$L6=AK$4),2,IF(AND($L6<>AK$4,AK5=2),AK5,IF($L6<>AK$4,0,1)))) -> 0 | AL6: =IF(OR(ROW()=5,$U5<>$U6),0,IF(AND($P6=1,$L6=AL$4),2,IF(AND($L6<>AL$4,AL5=2),AL5,IF($L6<>AL$4,0,1)))) -> 0
A7: 2326 | B7: A.1.2 | C7: Does the risk governance plan include range of assets to include: people, processes, data and technology? | D7: Yes | G7: Enterprise Risk Management | H7: Risk Governance Plan | I7: A.1 Enterprise Risk Governance | L7: 2 | M7: 2 | P7: =IF($L7="","",IF($D7="Yes",1,IF($D7="No",2,IF($D7="N/A",3,0)))) -> 1 | Q7: =IF(AND(Drops!$D$45>1,OR(U7<>U6,AND(ROW()=5,U6=U7))),VLOOKUP(U7,Drops!$D$26:$E$44,2,FALSE),"") | R7: =IF(Q7<>"",ROW(),"") | S7: =OFFSET(AC7,,L7-1) -> 1 | T7: =IF(OR(V7<>V6,U7<>U6,AND(V7<>V6,W7<>W6),AND(V7<>V6,W7<>W6,X7<>X6),AND(V7<>V6,W7<>W6,X7<>X6,Y7<>Y6),AND(V7<>V6,W7<>W6,X7<>X6,Y7<>Y6,Z7<>Z6),L7-L6>1),1,0) -> 0 | U7: A | V7: 1 | W7: 2 | X7: 0 | Y7: 0 | Z7: 0 | AA7: =IF(ROW()=5,1,IF(OR(AH7=1,P7>0,T7=1),1,IF(OR(AND(AH7=2,AI7=1),AND(AI7=2,AJ7=1),AND(AJ7=2,AK7=1),AND(AK7=2,AL7=1)),1,0))) -> 1 | AB7: =IF(L8>L7,1,0) -> 0 | AC7: =IF(ROW()=5,P7,IF(AND($P7>1,AC$4=$L7),$P7,IF(AND($U7=$U6,V7=V6),AC6,IF(AND($L7=AC$4,P7=1),P7,0)))) -> 1 | AD7: =IF(AC7>1,AC7,IF(AND($P7>1,AD$4=$L7),$P7,IF(AND($U7=$U6,W7=W6),AD6,IF(AND($L7=AD$4,P7=1),P7,0)))) -> 1 | AE7: =IF(AD7>1,AD7,IF(AND($P7>1,AE$4=$L7),$P7,IF(AND($U7=$U6,X7=X6),AE6,IF(AND($L7=AE$4,P7=1),P7,0)))) -> 0 | AF7: =IF(AE7>1,AE7,IF(AND($P7>1,AF$4=$L7),$P7,IF(AND($U7=$U6,Y7=Y6),AF6,IF(AND($L7=AF$4,P7=1),P7,0)))) -> 0 | AG7: =IF(AF7>1,AF7,IF(AND($P7>1,AG$4=$L7),$P7,IF(AND($U7=$U6,Z7=Z6),AG6,IF(AND($L7=AG$4,P7=1),P7,0)))) -> 0 | AH7: =IF(AND($P7=1,$L7=AH$4),2,IF(AND($L7<>AH$4,AH6=2),AH6,IF($L7<>AH$4,0,1))) -> 2 | AI7: =IF(OR(ROW()=5,$U6<>$U7),0,IF(AND($P7=1,$L7=AI$4),2,IF(AND($L7<>AI$4,AI6=2),AI6,IF($L7<>AI$4,0,1)))) -> 2 | AJ7: =IF(OR(ROW()=5,$U6<>$U7),0,IF(AND($P7=1,$L7=AJ$4),2,IF(AND($L7<>AJ$4,AJ6=2),AJ6,IF($L7<>AJ$4,0,1)))) -> 0 | AK7: =IF(OR(ROW()=5,$U6<>$U7),0,IF(AND($P7=1,$L7=AK$4),2,IF(AND($L7<>AK$4,AK6=2),AK6,IF($L7<>AK$4,0,1)))) -> 0 | AL7: =IF(OR(ROW()=5,$U6<>$U7),0,IF(AND($P7=1,$L7=AL$4),2,IF(AND($L7<>AL$4,AL6=2),AL6,IF($L7<>AL$4,0,1)))) -> 0
A8: 2420 | B8: A.1.3 | C8: Does the risk governance plan include range of internal and external threats to include: malicious, natural, accidental, cyber, business changes (transaction volume)? | D8: Yes | G8: Enterprise Risk Management | H8: Risk Governance Plan | I8: A.1 Enterprise Risk Governance | L8: 2 | M8: 3 | P8: =IF($L8="","",IF($D8="Yes",1,IF($D8="No",2,IF($D8="N/A",3,0)))) -> 1 | Q8: =IF(AND(Drops!$D$45>1,OR(U8<>U7,AND(ROW()=5,U7=U8))),VLOOKUP(U8,Drops!$D$26:$E$44,2,FALSE),"") | R8: =IF(Q8<>"",ROW(),"") | S8: =OFFSET(AC8,,L8-1) -> 1 | T8: =IF(OR(V8<>V7,U8<>U7,AND(V8<>V7,W8<>W7),AND(V8<>V7,W8<>W7,X8<>X7),AND(V8<>V7,W8<>W7,X8<>X7,Y8<>Y7),AND(V8<>V7,W8<>W7,X8<>X7,Y8<>Y7,Z8<>Z7),L8-L7>1),1,0) -> 0 | U8: A | V8: 1 | W8: 3 | X8: 0 | Y8: 0 | Z8: 0 | AA8: =IF(ROW()=5,1,IF(OR(AH8=1,P8>0,T8=1),1,IF(OR(AND(AH8=2,AI8=1),AND(AI8=2,AJ8=1),AND(AJ8=2,AK8=1),AND(AK8=2,AL8=1)),1,0))) -> 1 | AB8: =IF(L9>L8,1,0) -> 0 | AC8: =IF(ROW()=5,P8,IF(AND($P8>1,AC$4=$L8),$P8,IF(AND($U8=$U7,V8=V7),AC7,IF(AND($L8=AC$4,P8=1),P8,0)))) -> 1 | AD8: =IF(AC8>1,AC8,IF(AND($P8>1,AD$4=$L8),$P8,IF(AND($U8=$U7,W8=W7),AD7,IF(AND($L8=AD$4,P8=1),P8,0)))) -> 1 | AE8: =IF(AD8>1,AD8,IF(AND($P8>1,AE$4=$L8),$P8,IF(AND($U8=$U7,X8=X7),AE7,IF(AND($L8=AE$4,P8=1),P8,0)))) -> 0 | AF8: =IF(AE8>1,AE8,IF(AND($P8>1,AF$4=$L8),$P8,IF(AND($U8=$U7,Y8=Y7),AF7,IF(AND($L8=AF$4,P8=1),P8,0)))) -> 0 | AG8: =IF(AF8>1,AF8,IF(AND($P8>1,AG$4=$L8),$P8,IF(AND($U8=$U7,Z8=Z7),AG7,IF(AND($L8=AG$4,P8=1),P8,0)))) -> 0 | AH8: =IF(AND($P8=1,$L8=AH$4),2,IF(AND($L8<>AH$4,AH7=2),AH7,IF($L8<>AH$4,0,1))) -> 2 | AI8: =IF(OR(ROW()=5,$U7<>$U8),0,IF(AND($P8=1,$L8=AI$4),2,IF(AND($L8<>AI$4,AI7=2),AI7,IF($L8<>AI$4,0,1)))) -> 2 | AJ8: =IF(OR(ROW()=5,$U7<>$U8),0,IF(AND($P8=1,$L8=AJ$4),2,IF(AND($L8<>AJ$4,AJ7=2),AJ7,IF($L8<>AJ$4,0,1)))) -> 0 | AK8: =IF(OR(ROW()=5,$U7<>$U8),0,IF(AND($P8=1,$L8=AK$4),2,IF(AND($L8<>AK$4,AK7=2),AK7,IF($L8<>AK$4,0,1)))) -> 0 | AL8: =IF(OR(ROW()=5,$U7<>$U8),0,IF(AND($P8=1,$L8=AL$4),2,IF(AND($L8<>AL$4,AL7=2),AL7,IF($L8<>AL$4,0,1)))) -> 0
A9: 2429 | B9: A.1.4 | C9: Does the risk governance plan include risk scenarios that address threats, vulnerabilities, likelihoods, and impacts that could impact people, processes, technologies, and facilities? | D9: Yes | G9: Enterprise Risk Management | H9: Risk Governance Plan | I9: A.1 Enterprise Risk Governance | L9: 2 | M9: 3 | P9: =IF($L9="","",IF($D9="Yes",1,IF($D9="No",2,IF($D9="N/A",3,0)))) -> 1 | Q9: =IF(AND(Drops!$D$45>1,OR(U9<>U8,AND(ROW()=5,U8=U9))),VLOOKUP(U9,Drops!$D$26:$E$44,2,FALSE),"") | R9: =IF(Q9<>"",ROW(),"") | S9: =OFFSET(AC9,,L9-1) -> 1 | T9: =IF(OR(V9<>V8,U9<>U8,AND(V9<>V8,W9<>W8),AND(V9<>V8,W9<>W8,X9<>X8),AND(V9<>V8,W9<>W8,X9<>X8,Y9<>Y8),AND(V9<>V8,W9<>W8,X9<>X8,Y9<>Y8,Z9<>Z8),L9-L8>1),1,0) -> 0 | U9: A | V9: 1 | W9: 4 | X9: 0 | Y9: 0 | Z9: 0 | AA9: =IF(ROW()=5,1,IF(OR(AH9=1,P9>0,T9=1),1,IF(OR(AND(AH9=2,AI9=1),AND(AI9=2,AJ9=1),AND(AJ9=2,AK9=1),AND(AK9=2,AL9=1)),1,0))) -> 1 | AB9: =IF(L10>L9,1,0) -> 0 | AC9: =IF(ROW()=5,P9,IF(AND($P9>1,AC$4=$L9),$P9,IF(AND($U9=$U8,V9=V8),AC8,IF(AND($L9=AC$4,P9=1),P9,0)))) -> 1 | AD9: =IF(AC9>1,AC9,IF(AND($P9>1,AD$4=$L9),$P9,IF(AND($U9=$U8,W9=W8),AD8,IF(AND($L9=AD$4,P9=1),P9,0)))) -> 1 | AE9: =IF(AD9>1,AD9,IF(AND($P9>1,AE$4=$L9),$P9,IF(AND($U9=$U8,X9=X8),AE8,IF(AND($L9=AE$4,P9=1),P9,0)))) -> 0 | AF9: =IF(AE9>1,AE9,IF(AND($P9>1,AF$4=$L9),$P9,IF(AND($U9=$U8,Y9=Y8),AF8,IF(AND($L9=AF$4,P9=1),P9,0)))) -> 0 | AG9: =IF(AF9>1,AF9,IF(AND($P9>1,AG$4=$L9),$P9,IF(AND($U9=$U8,Z9=Z8),AG8,IF(AND($L9=AG$4,P9=1),P9,0)))) -> 0 | AH9: =IF(AND($P9=1,$L9=AH$4),2,IF(AND($L9<>AH$4,AH8=2),AH8,IF($L9<>AH$4,0,1))) -> 2 | AI9: =IF(OR(ROW()=5,$U8<>$U9),0,IF(AND($P9=1,$L9=AI$4),2,IF(AND($L9<>AI$4,AI8=2),AI8,IF($L9<>AI$4,0,1)))) -> 2 | AJ9: =IF(OR(ROW()=5,$U8<>$U9),0,IF(AND($P9=1,$L9=AJ$4),2,IF(AND($L9<>AJ$4,AJ8=2),AJ8,IF($L9<>AJ$4,0,1)))) -> 0 | AK9: =IF(OR(ROW()=5,$U8<>$U9),0,IF(AND($P9=1,$L9=AK$4),2,IF(AND($L9<>AK$4,AK8=2),AK8,IF($L9<>AK$4,0,1)))) -> 0 | AL9: =IF(OR(ROW()=5,$U8<>$U9),0,IF(AND($P9=1,$L9=AL$4),2,IF(AND($L9<>AL$4,AL8=2),AL8,IF($L9<>AL$4,0,1)))) -> 0
A10: 4633 | B10: A.1.5 | C10: Does the organization have a governing body accountable to maintain the risk governance plan? | D10: Yes | G10: Enterprise Risk Management | H10: Risk Governance Plan | I10: A.1 Enterprise Risk Governance | L10: 2 | M10: 3 | P10: =IF($L10="","",IF($D10="Yes",1,IF($D10="No",2,IF($D10="N/A",3,0)))) -> 1 | Q10: =IF(AND(Drops!$D$45>1,OR(U10<>U9,AND(ROW()=5,U9=U10))),VLOOKUP(U10,Drops!$D$26:$E$44,2,FALSE),"") | R10: =IF(Q10<>"",ROW(),"") | S10: =OFFSET(AC10,,L10-1) -> 1 | T10: =IF(OR(V10<>V9,U10<>U9,AND(V10<>V9,W10<>W9),AND(V10<>V9,W10<>W9,X10<>X9),AND(V10<>V9,W10<>W9,X10<>X9,Y10<>Y9),AND(V10<>V9,W10<>W9,X10<>X9,Y10<>Y9,Z10<>Z9),L10-L9>1),1,0) -> 0 | U10: A | V10: 1 | W10: 5 | X10: 0 | Y10: 0 | Z10: 0 | AA10: =IF(ROW()=5,1,IF(OR(AH10=1,P10>0,T10=1),1,IF(OR(AND(AH10=2,AI10=1),AND(AI10=2,AJ10=1),AND(AJ10=2,AK10=1),AND(AK10=2,AL10=1)),1,0))) -> 1 | AB10: =IF(L11>L10,1,0) -> 0 | AC10: =IF(ROW()=5,P10,IF(AND($P10>1,AC$4=$L10),$P10,IF(AND($U10=$U9,V10=V9),AC9,IF(AND($L10=AC$4,P10=1),P10,0)))) -> 1 | AD10: =IF(AC10>1,AC10,IF(AND($P10>1,AD$4=$L10),$P10,IF(AND($U10=$U9,W10=W9),AD9,IF(AND($L10=AD$4,P10=1),P10,0)))) -> 1 | AE10: =IF(AD10>1,AD10,IF(AND($P10>1,AE$4=$L10),$P10,IF(AND($U10=$U9,X10=X9),AE9,IF(AND($L10=AE$4,P10=1),P10,0)))) -> 0 | AF10: =IF(AE10>1,AE10,IF(AND($P10>1,AF$4=$L10),$P10,IF(AND($U10=$U9,Y10=Y9),AF9,IF(AND($L10=AF$4,P10=1),P10,0)))) -> 0 | AG10: =IF(AF10>1,AF10,IF(AND($P10>1,AG$4=$L10),$P10,IF(AND($U10=$U9,Z10=Z9),AG9,IF(AND($L10=AG$4,P10=1),P10,0)))) -> 0 | AH10: =IF(AND($P10=1,$L10=AH$4),2,IF(AND($L10<>AH$4,AH9=2),AH9,IF($L10<>AH$4,0,1))) -> 2 | AI10: =IF(OR(ROW()=5,$U9<>$U10),0,IF(AND($P10=1,$L10=AI$4),2,IF(AND($L10<>AI$4,AI9=2),AI9,IF($L10<>AI$4,0,1)))) -> 2 | AJ10: =IF(OR(ROW()=5,$U9<>$U10),0,IF(AND($P10=1,$L10=AJ$4),2,IF(AND($L10<>AJ$4,AJ9=2),AJ9,IF($L10<>AJ$4,0,1)))) -> 0 | AK10: =IF(OR(ROW()=5,$U9<>$U10),0,IF(AND($P10=1,$L10=AK$4),2,IF(AND($L10<>AK$4,AK9=2),AK9,IF($L10<>AK$4,0,1)))) -> 0 | AL10: =IF(OR(ROW()=5,$U9<>$U10),0,IF(AND($P10=1,$L10=AL$4),2,IF(AND($L10<>AL$4,AL9=2),AL9,IF($L10<>AL$4,0,1)))) -> 0
A11: 4635 | B11: A.1.7 | C11: Is the risk governance plan approved by senior management and/or board of directors? | D11: Yes | G11: Enterprise Risk Management | H11: Risk Governance Plan | I11: A.1 Enterprise Risk Governance | L11: 2 | M11: 3 | P11: =IF($L11="","",IF($D11="Yes",1,IF($D11="No",2,IF($D11="N/A",3,0)))) -> 1 | Q11: =IF(AND(Drops!$D$45>1,OR(U11<>U10,AND(ROW()=5,U10=U11))),VLOOKUP(U11,Drops!$D$26:$E$44,2,FALSE),"") | R11: =IF(Q11<>"",ROW(),"") | S11: =OFFSET(AC11,,L11-1) -> 1 | T11: =IF(OR(V11<>V10,U11<>U10,AND(V11<>V10,W11<>W10),AND(V11<>V10,W11<>W10,X11<>X10),AND(V11<>V10,W11<>W10,X11<>X10,Y11<>Y10),AND(V11<>V10,W11<>W10,X11<>X10,Y11<>Y10,Z11<>Z10),L11-L10>1),1,0) -> 0 | U11: A | V11: 1 | W11: 7 | X11: 0 | Y11: 0 | Z11: 0 | AA11: =IF(ROW()=5,1,IF(OR(AH11=1,P11>0,T11=1),1,IF(OR(AND(AH11=2,AI11=1),AND(AI11=2,AJ11=1),AND(AJ11=2,AK11=1),AND(AK11=2,AL11=1)),1,0))) -> 1 | AB11: =IF(L12>L11,1,0) -> 0 | AC11: =IF(ROW()=5,P11,IF(AND($P11>1,AC$4=$L11),$P11,IF(AND($U11=$U10,V11=V10),AC10,IF(AND($L11=AC$4,P11=1),P11,0)))) -> 1 | AD11: =IF(AC11>1,AC11,IF(AND($P11>1,AD$4=$L11),$P11,IF(AND($U11=$U10,W11=W10),AD10,IF(AND($L11=AD$4,P11=1),P11,0)))) -> 1 | AE11: =IF(AD11>1,AD11,IF(AND($P11>1,AE$4=$L11),$P11,IF(AND($U11=$U10,X11=X10),AE10,IF(AND($L11=AE$4,P11=1),P11,0)))) -> 0 | AF11: =IF(AE11>1,AE11,IF(AND($P11>1,AF$4=$L11),$P11,IF(AND($U11=$U10,Y11=Y10),AF10,IF(AND($L11=AF$4,P11=1),P11,0)))) -> 0 | AG11: =IF(AF11>1,AF11,IF(AND($P11>1,AG$4=$L11),$P11,IF(AND($U11=$U10,Z11=Z10),AG10,IF(AND($L11=AG$4,P11=1),P11,0)))) -> 0 | AH11: =IF(AND($P11=1,$L11=AH$4),2,IF(AND($L11<>AH$4,AH10=2),AH10,IF($L11<>AH$4,0,1))) -> 2 | AI11: =IF(OR(ROW()=5,$U10<>$U11),0,IF(AND($P11=1,$L11=AI$4),2,IF(AND($L11<>AI$4,AI10=2),AI10,IF($L11<>AI$4,0,1)))) -> 2 | AJ11: =IF(OR(ROW()=5,$U10<>$U11),0,IF(AND($P11=1,$L11=AJ$4),2,IF(AND($L11<>AJ$4,AJ10=2),AJ10,IF($L11<>AJ$4,0,1)))) -> 0 | AK11: =IF(OR(ROW()=5,$U10<>$U11),0,IF(AND($P11=1,$L11=AK$4),2,IF(AND($L11<>AK$4,AK10=2),AK10,IF($L11<>AK$4,0,1)))) -> 0 | AL11: =IF(OR(ROW()=5,$U10<>$U11),0,IF(AND($P11=1,$L11=AL$4),2,IF(AND($L11<>AL$4,AL10=2),AL10,IF($L11<>AL$4,0,1)))) -> 0
A12: 4636 | B12: A.1.8 | C12: Is training provided to employees regarding risk expectations and their obligations? | D12: Yes | G12: Enterprise Risk Management | H12: Risk Governance Plan | I12: A.1 Enterprise Risk Governance | L12: 2 | M12: 3 | P12: =IF($L12="","",IF($D12="Yes",1,IF($D12="No",2,IF($D12="N/A",3,0)))) -> 1 | Q12: =IF(AND(Drops!$D$45>1,OR(U12<>U11,AND(ROW()=5,U11=U12))),VLOOKUP(U12,Drops!$D$26:$E$44,2,FALSE),"") | R12: =IF(Q12<>"",ROW(),"") | S12: =OFFSET(AC12,,L12-1) -> 1 | T12: =IF(OR(V12<>V11,U12<>U11,AND(V12<>V11,W12<>W11),AND(V12<>V11,W12<>W11,X12<>X11),AND(V12<>V11,W12<>W11,X12<>X11,Y12<>Y11),AND(V12<>V11,W12<>W11,X12<>X11,Y12<>Y11,Z12<>Z11),L12-L11>1),1,0) -> 0 | U12: A | V12: 1 | W12: 8 | X12: 0 | Y12: 0 | Z12: 0 | AA12: =IF(ROW()=5,1,IF(OR(AH12=1,P12>0,T12=1),1,IF(OR(AND(AH12=2,AI12=1),AND(AI12=2,AJ12=1),AND(AJ12=2,AK12=1),AND(AK12=2,AL12=1)),1,0))) -> 1 | AB12: =IF(L13>L12,1,0) -> 0 | AC12: =IF(ROW()=5,P12,IF(AND($P12>1,AC$4=$L12),$P12,IF(AND($U12=$U11,V12=V11),AC11,IF(AND($L12=AC$4,P12=1),P12,0)))) -> 1 | AD12: =IF(AC12>1,AC12,IF(AND($P12>1,AD$4=$L12),$P12,IF(AND($U12=$U11,W12=W11),AD11,IF(AND($L12=AD$4,P12=1),P12,0)))) -> 1 | AE12: =IF(AD12>1,AD12,IF(AND($P12>1,AE$4=$L12),$P12,IF(AND($U12=$U11,X12=X11),AE11,IF(AND($L12=AE$4,P12=1),P12,0)))) -> 0 | AF12: =IF(AE12>1,AE12,IF(AND($P12>1,AF$4=$L12),$P12,IF(AND($U12=$U11,Y12=Y11),AF11,IF(AND($L12=AF$4,P12=1),P12,0)))) -> 0 | AG12: =IF(AF12>1,AF12,IF(AND($P12>1,AG$4=$L12),$P12,IF(AND($U12=$U11,Z12=Z11),AG11,IF(AND($L12=AG$4,P12=1),P12,0)))) -> 0 | AH12: =IF(AND($P12=1,$L12=AH$4),2,IF(AND($L12<>AH$4,AH11=2),AH11,IF($L12<>AH$4,0,1))) -> 2 | AI12: =IF(OR(ROW()=5,$U11<>$U12),0,IF(AND($P12=1,$L12=AI$4),2,IF(AND($L12<>AI$4,AI11=2),AI11,IF($L12<>AI$4,0,1)))) -> 2 | AJ12: =IF(OR(ROW()=5,$U11<>$U12),0,IF(AND($P12=1,$L12=AJ$4),2,IF(AND($L12<>AJ$4,AJ11=2),AJ11,IF($L12<>AJ$4,0,1)))) -> 0 | AK12: =IF(OR(ROW()=5,$U11<>$U12),0,IF(AND($P12=1,$L12=AK$4),2,IF(AND($L12<>AK$4,AK11=2),AK11,IF($L12<>AK$4,0,1)))) -> 0 | AL12: =IF(OR(ROW()=5,$U11<>$U12),0,IF(AND($P12=1,$L12=AL$4),2,IF(AND($L12<>AL$4,AL11=2),AL11,IF($L12<>AL$4,0,1)))) -> 0
A13: 5837 | B13: A.1.9 | C13: Does the risk governance plan include the identification of the systems/products/services that support organizational priorities? | D13: Yes | G13: Enterprise Risk Management | H13: Risk Governance Plan | L13: 2 | M13: 3 | P13: =IF($L13="","",IF($D13="Yes",1,IF($D13="No",2,IF($D13="N/A",3,0)))) -> 1 | Q13: =IF(AND(Drops!$D$45>1,OR(U13<>U12,AND(ROW()=5,U12=U13))),VLOOKUP(U13,Drops!$D$26:$E$44,2,FALSE),"") | R13: =IF(Q13<>"",ROW(),"") | S13: =OFFSET(AC13,,L13-1) -> 1 | T13: =IF(OR(V13<>V12,U13<>U12,AND(V13<>V12,W13<>W12),AND(V13<>V12,W13<>W12,X13<>X12),AND(V13<>V12,W13<>W12,X13<>X12,Y13<>Y12),AND(V13<>V12,W13<>W12,X13<>X12,Y13<>Y12,Z13<>Z12),L13-L12>1),1,0) -> 0 | U13: A | V13: 1 | W13: 9 | X13: 0 | Y13: 0 | Z13: 0 | AA13: =IF(ROW()=5,1,IF(OR(AH13=1,P13>0,T13=1),1,IF(OR(AND(AH13=2,AI13=1),AND(AI13=2,AJ13=1),AND(AJ13=2,AK13=1),AND(AK13=2,AL13=1)),1,0))) -> 1 | AB13: =IF(L14>L13,1,0) -> 0 | AC13: =IF(ROW()=5,P13,IF(AND($P13>1,AC$4=$L13),$P13,IF(AND($U13=$U12,V13=V12),AC12,IF(AND($L13=AC$4,P13=1),P13,0)))) -> 1 | AD13: =IF(AC13>1,AC13,IF(AND($P13>1,AD$4=$L13),$P13,IF(AND($U13=$U12,W13=W12),AD12,IF(AND($L13=AD$4,P13=1),P13,0)))) -> 1 | AE13: =IF(AD13>1,AD13,IF(AND($P13>1,AE$4=$L13),$P13,IF(AND($U13=$U12,X13=X12),AE12,IF(AND($L13=AE$4,P13=1),P13,0)))) -> 0 | AF13: =IF(AE13>1,AE13,IF(AND($P13>1,AF$4=$L13),$P13,IF(AND($U13=$U12,Y13=Y12),AF12,IF(AND($L13=AF$4,P13=1),P13,0)))) -> 0 | AG13: =IF(AF13>1,AF13,IF(AND($P13>1,AG$4=$L13),$P13,IF(AND($U13=$U12,Z13=Z12),AG12,IF(AND($L13=AG$4,P13=1),P13,0)))) -> 0 | AH13: =IF(AND($P13=1,$L13=AH$4),2,IF(AND($L13<>AH$4,AH12=2),AH12,IF($L13<>AH$4,0,1))) -> 2 | AI13: =IF(OR(ROW()=5,$U12<>$U13),0,IF(AND($P13=1,$L13=AI$4),2,IF(AND($L13<>AI$4,AI12=2),AI12,IF($L13<>AI$4,0,1)))) -> 2 | AJ13: =IF(OR(ROW()=5,$U12<>$U13),0,IF(AND($P13=1,$L13=AJ$4),2,IF(AND($L13<>AJ$4,AJ12=2),AJ12,IF($L13<>AJ$4,0,1)))) -> 0 | AK13: =IF(OR(ROW()=5,$U12<>$U13),0,IF(AND($P13=1,$L13=AK$4),2,IF(AND($L13<>AK$4,AK12=2),AK12,IF($L13<>AK$4,0,1)))) -> 0 | AL13: =IF(OR(ROW()=5,$U12<>$U13),0,IF(AND($P13=1,$L13=AL$4),2,IF(AND($L13<>AL$4,AL12=2),AL12,IF($L13<>AL$4,0,1)))) -> 0
A14: 5838 | B14: A.1.10 | C14: Does the risk governance plan include the alignment to the organization's mission, objectives, and stakeholders to inform roles and responsibilities for risk management decisions? | D14: Yes | G14: Enterprise Risk Management | H14: Risk Governance Plan | L14: 2 | M14: 3 | P14: =IF($L14="","",IF($D14="Yes",1,IF($D14="No",2,IF($D14="N/A",3,0)))) -> 1 | Q14: =IF(AND(Drops!$D$45>1,OR(U14<>U13,AND(ROW()=5,U13=U14))),VLOOKUP(U14,Drops!$D$26:$E$44,2,FALSE),"") | R14: =IF(Q14<>"",ROW(),"") | S14: =OFFSET(AC14,,L14-1) -> 1 | T14: =IF(OR(V14<>V13,U14<>U13,AND(V14<>V13,W14<>W13),AND(V14<>V13,W14<>W13,X14<>X13),AND(V14<>V13,W14<>W13,X14<>X13,Y14<>Y13),AND(V14<>V13,W14<>W13,X14<>X13,Y14<>Y13,Z14<>Z13),L14-L13>1),1,0) -> 0 | U14: A | V14: 1 | W14: 10 | X14: 0 | Y14: 0 | Z14: 0 | AA14: =IF(ROW()=5,1,IF(OR(AH14=1,P14>0,T14=1),1,IF(OR(AND(AH14=2,AI14=1),AND(AI14=2,AJ14=1),AND(AJ14=2,AK14=1),AND(AK14=2,AL14=1)),1,0))) -> 1 | AB14: =IF(L15>L14,1,0) -> 0 | AC14: =IF(ROW()=5,P14,IF(AND($P14>1,AC$4=$L14),$P14,IF(AND($U14=$U13,V14=V13),AC13,IF(AND($L14=AC$4,P14=1),P14,0)))) -> 1 | AD14: =IF(AC14>1,AC14,IF(AND($P14>1,AD$4=$L14),$P14,IF(AND($U14=$U13,W14=W13),AD13,IF(AND($L14=AD$4,P14=1),P14,0)))) -> 1 | AE14: =IF(AD14>1,AD14,IF(AND($P14>1,AE$4=$L14),$P14,IF(AND($U14=$U13,X14=X13),AE13,IF(AND($L14=AE$4,P14=1),P14,0)))) -> 0 | AF14: =IF(AE14>1,AE14,IF(AND($P14>1,AF$4=$L14),$P14,IF(AND($U14=$U13,Y14=Y13),AF13,IF(AND($L14=AF$4,P14=1),P14,0)))) -> 0 | AG14: =IF(AF14>1,AF14,IF(AND($P14>1,AG$4=$L14),$P14,IF(AND($U14=$U13,Z14=Z13),AG13,IF(AND($L14=AG$4,P14=1),P14,0)))) -> 0 | AH14: =IF(AND($P14=1,$L14=AH$4),2,IF(AND($L14<>AH$4,AH13=2),AH13,IF($L14<>AH$4,0,1))) -> 2 | AI14: =IF(OR(ROW()=5,$U13<>$U14),0,IF(AND($P14=1,$L14=AI$4),2,IF(AND($L14<>AI$4,AI13=2),AI13,IF($L14<>AI$4,0,1)))) -> 2 | AJ14: =IF(OR(ROW()=5,$U13<>$U14),0,IF(AND($P14=1,$L14=AJ$4),2,IF(AND($L14<>AJ$4,AJ13=2),AJ13,IF($L14<>AJ$4,0,1)))) -> 0 | AK14: =IF(OR(ROW()=5,$U13<>$U14),0,IF(AND($P14=1,$L14=AK$4),2,IF(AND($L14<>AK$4,AK13=2),AK13,IF($L14<>AK$4,0,1)))) -> 0 | AL14: =IF(OR(ROW()=5,$U13<>$U14),0,IF(AND($P14=1,$L14=AL$4),2,IF(AND($L14<>AL$4,AL13=2),AL13,IF($L14<>AL$4,0,1)))) -> 0
A15: 5839 | B15: A.1.11 | C15: Does the risk governance plan include the establishment and communication of the priorities of activities? | D15: Yes | G15: Enterprise Risk Management | H15: Risk Governance Plan | L15: 2 | M15: 3 | P15: =IF($L15="","",IF($D15="Yes",1,IF($D15="No",2,IF($D15="N/A",3,0)))) -> 1 | Q15: =IF(AND(Drops!$D$45>1,OR(U15<>U14,AND(ROW()=5,U14=U15))),VLOOKUP(U15,Drops!$D$26:$E$44,2,FALSE),"") | R15: =IF(Q15<>"",ROW(),"") | S15: =OFFSET(AC15,,L15-1) -> 1 | T15: =IF(OR(V15<>V14,U15<>U14,AND(V15<>V14,W15<>W14),AND(V15<>V14,W15<>W14,X15<>X14),AND(V15<>V14,W15<>W14,X15<>X14,Y15<>Y14),AND(V15<>V14,W15<>W14,X15<>X14,Y15<>Y14,Z15<>Z14),L15-L14>1),1,0) -> 0 | U15: A | V15: 1 | W15: 11 | X15: 0 | Y15: 0 | Z15: 0 | AA15: =IF(ROW()=5,1,IF(OR(AH15=1,P15>0,T15=1),1,IF(OR(AND(AH15=2,AI15=1),AND(AI15=2,AJ15=1),AND(AJ15=2,AK15=1),AND(AK15=2,AL15=1)),1,0))) -> 1 | AB15: =IF(L16>L15,1,0) -> 0 | AC15: =IF(ROW()=5,P15,IF(AND($P15>1,AC$4=$L15),$P15,IF(AND($U15=$U14,V15=V14),AC14,IF(AND($L15=AC$4,P15=1),P15,0)))) -> 1 | AD15: =IF(AC15>1,AC15,IF(AND($P15>1,AD$4=$L15),$P15,IF(AND($U15=$U14,W15=W14),AD14,IF(AND($L15=AD$4,P15=1),P15,0)))) -> 1 | AE15: =IF(AD15>1,AD15,IF(AND($P15>1,AE$4=$L15),$P15,IF(AND($U15=$U14,X15=X14),AE14,IF(AND($L15=AE$4,P15=1),P15,0)))) -> 0 | AF15: =IF(AE15>1,AE15,IF(AND($P15>1,AF$4=$L15),$P15,IF(AND($U15=$U14,Y15=Y14),AF14,IF(AND($L15=AF$4,P15=1),P15,0)))) -> 0 | AG15: =IF(AF15>1,AF15,IF(AND($P15>1,AG$4=$L15),$P15,IF(AND($U15=$U14,Z15=Z14),AG14,IF(AND($L15=AG$4,P15=1),P15,0)))) -> 0 | AH15: =IF(AND($P15=1,$L15=AH$4),2,IF(AND($L15<>AH$4,AH14=2),AH14,IF($L15<>AH$4,0,1))) -> 2 | AI15: =IF(OR(ROW()=5,$U14<>$U15),0,IF(AND($P15=1,$L15=AI$4),2,IF(AND($L15<>AI$4,AI14=2),AI14,IF($L15<>AI$4,0,1)))) -> 2 | AJ15: =IF(OR(ROW()=5,$U14<>$U15),0,IF(AND($P15=1,$L15=AJ$4),2,IF(AND($L15<>AJ$4,AJ14=2),AJ14,IF($L15<>AJ$4,0,1)))) -> 0 | AK15: =IF(OR(ROW()=5,$U14<>$U15),0,IF(AND($P15=1,$L15=AK$4),2,IF(AND($L15<>AK$4,AK14=2),AK14,IF($L15<>AK$4,0,1)))) -> 0 | AL15: =IF(OR(ROW()=5,$U14<>$U15),0,IF(AND($P15=1,$L15=AL$4),2,IF(AND($L15<>AL$4,AL14=2),AL14,IF($L15<>AL$4,0,1)))) -> 0
A16: 4412 | B16: A.2 | C16: Are there Subject Matter Experts and/or groups assigned to assess risk for different categories e.g., operational, reputational, regulatory, technology, privacy, financial, etc.? If no, please explain any exclusions in the additional information field. | D16: Yes | G16: Enterprise Risk Management | H16: Risk Governance - Personnel | I16: A.1 Enterprise Risk Governance | J16: 6.1.2 Information Security Risk Asssessment|8.2 Information Security Risk Assessment | L16: 1 | M16: 3 | P16: =IF($L16="","",IF($D16="Yes",1,IF($D16="No",2,IF($D16="N/A",3,0)))) -> 1 | Q16: =IF(AND(Drops!$D$45>1,OR(U16<>U15,AND(ROW()=5,U15=U16))),VLOOKUP(U16,Drops!$D$26:$E$44,2,FALSE),"") | R16: =IF(Q16<>"",ROW(),"") | S16: =OFFSET(AC16,,L16-1) -> 1 | T16: =IF(OR(V16<>V15,U16<>U15,AND(V16<>V15,W16<>W15),AND(V16<>V15,W16<>W15,X16<>X15),AND(V16<>V15,W16<>W15,X16<>X15,Y16<>Y15),AND(V16<>V15,W16<>W15,X16<>X15,Y16<>Y15,Z16<>Z15),L16-L15>1),1,0) -> 1 | U16: A | V16: 2 | W16: 0 | X16: 0 | Y16: 0 | Z16: 0 | AA16: =IF(ROW()=5,1,IF(OR(AH16=1,P16>0,T16=1),1,IF(OR(AND(AH16=2,AI16=1),AND(AI16=2,AJ16=1),AND(AJ16=2,AK16=1),AND(AK16=2,AL16=1)),1,0))) -> 1 | AB16: =IF(L17>L16,1,0) -> 1 | AC16: =IF(ROW()=5,P16,IF(AND($P16>1,AC$4=$L16),$P16,IF(AND($U16=$U15,V16=V15),AC15,IF(AND($L16=AC$4,P16=1),P16,0)))) -> 1 | AD16: =IF(AC16>1,AC16,IF(AND($P16>1,AD$4=$L16),$P16,IF(AND($U16=$U15,W16=W15),AD15,IF(AND($L16=AD$4,P16=1),P16,0)))) -> 0 | AE16: =IF(AD16>1,AD16,IF(AND($P16>1,AE$4=$L16),$P16,IF(AND($U16=$U15,X16=X15),AE15,IF(AND($L16=AE$4,P16=1),P16,0)))) -> 0 | AF16: =IF(AE16>1,AE16,IF(AND($P16>1,AF$4=$L16),$P16,IF(AND($U16=$U15,Y16=Y15),AF15,IF(AND($L16=AF$4,P16=1),P16,0)))) -> 0 | AG16: =IF(AF16>1,AF16,IF(AND($P16>1,AG$4=$L16),$P16,IF(AND($U16=$U15,Z16=Z15),AG15,IF(AND($L16=AG$4,P16=1),P16,0)))) -> 0 | AH16: =IF(AND($P16=1,$L16=AH$4),2,IF(AND($L16<>AH$4,AH15=2),AH15,IF($L16<>AH$4,0,1))) -> 2 | AI16: =IF(OR(ROW()=5,$U15<>$U16),0,IF(AND($P16=1,$L16=AI$4),2,IF(AND($L16<>AI$4,AI15=2),AI15,IF($L16<>AI$4,0,1)))) -> 2 | AJ16: =IF(OR(ROW()=5,$U15<>$U16),0,IF(AND($P16=1,$L16=AJ$4),2,IF(AND($L16<>AJ$4,AJ15=2),AJ15,IF($L16<>AJ$4,0,1)))) -> 0 | AK16: =IF(OR(ROW()=5,$U15<>$U16),0,IF(AND($P16=1,$L16=AK$4),2,IF(AND($L16<>AK$4,AK15=2),AK15,IF($L16<>AK$4,0,1)))) -> 0 | AL16: =IF(OR(ROW()=5,$U15<>$U16),0,IF(AND($P16=1,$L16=AL$4),2,IF(AND($L16<>AL$4,AL15=2),AL15,IF($L16<>AL$4,0,1)))) -> 0
A17: 4637 | B17: A.2.1 | C17: Do risk assessment personnel maintain relevant professional certifications? | D17: Yes | G17: Enterprise Risk Management | H17: Risk Governance - Personnel | L17: 2 | M17: 3 | P17: =IF($L17="","",IF($D17="Yes",1,IF($D17="No",2,IF($D17="N/A",3,0)))) -> 1 | Q17: =IF(AND(Drops!$D$45>1,OR(U17<>U16,AND(ROW()=5,U16=U17))),VLOOKUP(U17,Drops!$D$26:$E$44,2,FALSE),"") | R17: =IF(Q17<>"",ROW(),"") | S17: =OFFSET(AC17,,L17-1) -> 1 | T17: =IF(OR(V17<>V16,U17<>U16,AND(V17<>V16,W17<>W16),AND(V17<>V16,W17<>W16,X17<>X16),AND(V17<>V16,W17<>W16,X17<>X16,Y17<>Y16),AND(V17<>V16,W17<>W16,X17<>X16,Y17<>Y16,Z17<>Z16),L17-L16>1),1,0) -> 0 | U17: A | V17: 2 | W17: 1 | X17: 0 | Y17: 0 | Z17: 0 | AA17: =IF(ROW()=5,1,IF(OR(AH17=1,P17>0,T17=1),1,IF(OR(AND(AH17=2,AI17=1),AND(AI17=2,AJ17=1),AND(AJ17=2,AK17=1),AND(AK17=2,AL17=1)),1,0))) -> 1 | AB17: =IF(L18>L17,1,0) -> 0 | AC17: =IF(ROW()=5,P17,IF(AND($P17>1,AC$4=$L17),$P17,IF(AND($U17=$U16,V17=V16),AC16,IF(AND($L17=AC$4,P17=1),P17,0)))) -> 1 | AD17: =IF(AC17>1,AC17,IF(AND($P17>1,AD$4=$L17),$P17,IF(AND($U17=$U16,W17=W16),AD16,IF(AND($L17=AD$4,P17=1),P17,0)))) -> 1 | AE17: =IF(AD17>1,AD17,IF(AND($P17>1,AE$4=$L17),$P17,IF(AND($U17=$U16,X17=X16),AE16,IF(AND($L17=AE$4,P17=1),P17,0)))) -> 0 | AF17: =IF(AE17>1,AE17,IF(AND($P17>1,AF$4=$L17),$P17,IF(AND($U17=$U16,Y17=Y16),AF16,IF(AND($L17=AF$4,P17=1),P17,0)))) -> 0 | AG17: =IF(AF17>1,AF17,IF(AND($P17>1,AG$4=$L17),$P17,IF(AND($U17=$U16,Z17=Z16),AG16,IF(AND($L17=AG$4,P17=1),P17,0)))) -> 0 | AH17: =IF(AND($P17=1,$L17=AH$4),2,IF(AND($L17<>AH$4,AH16=2),AH16,IF($L17<>AH$4,0,1))) -> 2 | AI17: =IF(OR(ROW()=5,$U16<>$U17),0,IF(AND($P17=1,$L17=AI$4),2,IF(AND($L17<>AI$4,AI16=2),AI16,IF($L17<>AI$4,0,1)))) -> 2 | AJ17: =IF(OR(ROW()=5,$U16<>$U17),0,IF(AND($P17=1,$L17=AJ$4),2,IF(AND($L17<>AJ$4,AJ16=2),AJ16,IF($L17<>AJ$4,0,1)))) -> 0 | AK17: =IF(OR(ROW()=5,$U16<>$U17),0,IF(AND($P17=1,$L17=AK$4),2,IF(AND($L17<>AK$4,AK16=2),AK16,IF($L17<>AK$4,0,1)))) -> 0 | AL17: =IF(OR(ROW()=5,$U16<>$U17),0,IF(AND($P17=1,$L17=AL$4),2,IF(AND($L17<>AL$4,AL16=2),AL16,IF($L17<>AL$4,0,1)))) -> 0
A18: 4638 | B18: A.2.2 | C18: Do risk assessment personnel maintain contacts with relevant professional special interest groups, specialist forums or professional associations? | D18: Yes | G18: Enterprise Risk Management | H18: Risk Governance - Personnel | L18: 2 | M18: 3 | P18: =IF($L18="","",IF($D18="Yes",1,IF($D18="No",2,IF($D18="N/A",3,0)))) -> 1 | Q18: =IF(AND(Drops!$D$45>1,OR(U18<>U17,AND(ROW()=5,U17=U18))),VLOOKUP(U18,Drops!$D$26:$E$44,2,FALSE),"") | R18: =IF(Q18<>"",ROW(),"") | S18: =OFFSET(AC18,,L18-1) -> 1 | T18: =IF(OR(V18<>V17,U18<>U17,AND(V18<>V17,W18<>W17),AND(V18<>V17,W18<>W17,X18<>X17),AND(V18<>V17,W18<>W17,X18<>X17,Y18<>Y17),AND(V18<>V17,W18<>W17,X18<>X17,Y18<>Y17,Z18<>Z17),L18-L17>1),1,0) -> 0 | U18: A | V18: 2 | W18: 2 | X18: 0 | Y18: 0 | Z18: 0 | AA18: =IF(ROW()=5,1,IF(OR(AH18=1,P18>0,T18=1),1,IF(OR(AND(AH18=2,AI18=1),AND(AI18=2,AJ18=1),AND(AJ18=2,AK18=1),AND(AK18=2,AL18=1)),1,0))) -> 1 | AB18: =IF(L19>L18,1,0) -> 0 | AC18: =IF(ROW()=5,P18,IF(AND($P18>1,AC$4=$L18),$P18,IF(AND($U18=$U17,V18=V17),AC17,IF(AND($L18=AC$4,P18=1),P18,0)))) -> 1 | AD18: =IF(AC18>1,AC18,IF(AND($P18>1,AD$4=$L18),$P18,IF(AND($U18=$U17,W18=W17),AD17,IF(AND($L18=AD$4,P18=1),P18,0)))) -> 1 | AE18: =IF(AD18>1,AD18,IF(AND($P18>1,AE$4=$L18),$P18,IF(AND($U18=$U17,X18=X17),AE17,IF(AND($L18=AE$4,P18=1),P18,0)))) -> 0 | AF18: =IF(AE18>1,AE18,IF(AND($P18>1,AF$4=$L18),$P18,IF(AND($U18=$U17,Y18=Y17),AF17,IF(AND($L18=AF$4,P18=1),P18,0)))) -> 0 | AG18: =IF(AF18>1,AF18,IF(AND($P18>1,AG$4=$L18),$P18,IF(AND($U18=$U17,Z18=Z17),AG17,IF(AND($L18=AG$4,P18=1),P18,0)))) -> 0 | AH18: =IF(AND($P18=1,$L18=AH$4),2,IF(AND($L18<>AH$4,AH17=2),AH17,IF($L18<>AH$4,0,1))) -> 2 | AI18: =IF(OR(ROW()=5,$U17<>$U18),0,IF(AND($P18=1,$L18=AI$4),2,IF(AND($L18<>AI$4,AI17=2),AI17,IF($L18<>AI$4,0,1)))) -> 2 | AJ18: =IF(OR(ROW()=5,$U17<>$U18),0,IF(AND($P18=1,$L18=AJ$4),2,IF(AND($L18<>AJ$4,AJ17=2),AJ17,IF($L18<>AJ$4,0,1)))) -> 0 | AK18: =IF(OR(ROW()=5,$U17<>$U18),0,IF(AND($P18=1,$L18=AK$4),2,IF(AND($L18<>AK$4,AK17=2),AK17,IF($L18<>AK$4,0,1)))) -> 0 | AL18: =IF(OR(ROW()=5,$U17<>$U18),0,IF(AND($P18=1,$L18=AL$4),2,IF(AND($L18<>AL$4,AL17=2),AL17,IF($L18<>AL$4,0,1)))) -> 0
A19: 4639 | B19: A.2.3 | C19: Do risk assessment personnel participate in continuing education programs e.g., online training, webinars, seminars, etc.? | D19: Yes | G19: Enterprise Risk Management | H19: Risk Governance - Personnel | L19: 2 | M19: 3 | P19: =IF($L19="","",IF($D19="Yes",1,IF($D19="No",2,IF($D19="N/A",3,0)))) -> 1 | Q19: =IF(AND(Drops!$D$45>1,OR(U19<>U18,AND(ROW()=5,U18=U19))),VLOOKUP(U19,Drops!$D$26:$E$44,2,FALSE),"") | R19: =IF(Q19<>"",ROW(),"") | S19: =OFFSET(AC19,,L19-1) -> 1 | T19: =IF(OR(V19<>V18,U19<>U18,AND(V19<>V18,W19<>W18),AND(V19<>V18,W19<>W18,X19<>X18),AND(V19<>V18,W19<>W18,X19<>X18,Y19<>Y18),AND(V19<>V18,W19<>W18,X19<>X18,Y19<>Y18,Z19<>Z18),L19-L18>1),1,0) -> 0 | U19: A | V19: 2 | W19: 3 | X19: 0 | Y19: 0 | Z19: 0 | AA19: =IF(ROW()=5,1,IF(OR(AH19=1,P19>0,T19=1),1,IF(OR(AND(AH19=2,AI19=1),AND(AI19=2,AJ19=1),AND(AJ19=2,AK19=1),AND(AK19=2,AL19=1)),1,0))) -> 1 | AB19: =IF(L20>L19,1,0) -> 0 | AC19: =IF(ROW()=5,P19,IF(AND($P19>1,AC$4=$L19),$P19,IF(AND($U19=$U18,V19=V18),AC18,IF(AND($L19=AC$4,P19=1),P19,0)))) -> 1 | AD19: =IF(AC19>1,AC19,IF(AND($P19>1,AD$4=$L19),$P19,IF(AND($U19=$U18,W19=W18),AD18,IF(AND($L19=AD$4,P19=1),P19,0)))) -> 1 | AE19: =IF(AD19>1,AD19,IF(AND($P19>1,AE$4=$L19),$P19,IF(AND($U19=$U18,X19=X18),AE18,IF(AND($L19=AE$4,P19=1),P19,0)))) -> 0 | AF19: =IF(AE19>1,AE19,IF(AND($P19>1,AF$4=$L19),$P19,IF(AND($U19=$U18,Y19=Y18),AF18,IF(AND($L19=AF$4,P19=1),P19,0)))) -> 0 | AG19: =IF(AF19>1,AF19,IF(AND($P19>1,AG$4=$L19),$P19,IF(AND($U19=$U18,Z19=Z18),AG18,IF(AND($L19=AG$4,P19=1),P19,0)))) -> 0 | AH19: =IF(AND($P19=1,$L19=AH$4),2,IF(AND($L19<>AH$4,AH18=2),AH18,IF($L19<>AH$4,0,1))) -> 2 | AI19: =IF(OR(ROW()=5,$U18<>$U19),0,IF(AND($P19=1,$L19=AI$4),2,IF(AND($L19<>AI$4,AI18=2),AI18,IF($L19<>AI$4,0,1)))) -> 2 | AJ19: =IF(OR(ROW()=5,$U18<>$U19),0,IF(AND($P19=1,$L19=AJ$4),2,IF(AND($L19<>AJ$4,AJ18=2),AJ18,IF($L19<>AJ$4,0,1)))) -> 0 | AK19: =IF(OR(ROW()=5,$U18<>$U19),0,IF(AND($P19=1,$L19=AK$4),2,IF(AND($L19<>AK$4,AK18=2),AK18,IF($L19<>AK$4,0,1)))) -> 0 | AL19: =IF(OR(ROW()=5,$U18<>$U19),0,IF(AND($P19=1,$L19=AL$4),2,IF(AND($L19<>AL$4,AL18=2),AL18,IF($L19<>AL$4,0,1)))) -> 0
A20: 4413 | B20: A.2.5 | C20: Do all assessment groups utilize a consistent standardized framework for assessing risk? | D20: Yes | E20: Seismic's Risk Management Program is based off ISO 27005. | G20: Enterprise Risk Management | H20: Risk Governance - Personnel | J20: 6.1.2 Information Security Risk Asssessment|8.2 Information Security Risk Assessment | L20: 2 | M20: 3 | P20: =IF($L20="","",IF($D20="Yes",1,IF($D20="No",2,IF($D20="N/A",3,0)))) -> 1 | Q20: =IF(AND(Drops!$D$45>1,OR(U20<>U19,AND(ROW()=5,U19=U20))),VLOOKUP(U20,Drops!$D$26:$E$44,2,FALSE),"") | R20: =IF(Q20<>"",ROW(),"") | S20: =OFFSET(AC20,,L20-1) -> 1 | T20: =IF(OR(V20<>V19,U20<>U19,AND(V20<>V19,W20<>W19),AND(V20<>V19,W20<>W19,X20<>X19),AND(V20<>V19,W20<>W19,X20<>X19,Y20<>Y19),AND(V20<>V19,W20<>W19,X20<>X19,Y20<>Y19,Z20<>Z19),L20-L19>1),1,0) -> 0 | U20: A | V20: 2 | W20: 5 | X20: 0 | Y20: 0 | Z20: 0 | AA20: =IF(ROW()=5,1,IF(OR(AH20=1,P20>0,T20=1),1,IF(OR(AND(AH20=2,AI20=1),AND(AI20=2,AJ20=1),AND(AJ20=2,AK20=1),AND(AK20=2,AL20=1)),1,0))) -> 1 | AB20: =IF(L21>L20,1,0) -> 0 | AC20: =IF(ROW()=5,P20,IF(AND($P20>1,AC$4=$L20),$P20,IF(AND($U20=$U19,V20=V19),AC19,IF(AND($L20=AC$4,P20=1),P20,0)))) -> 1 | AD20: =IF(AC20>1,AC20,IF(AND($P20>1,AD$4=$L20),$P20,IF(AND($U20=$U19,W20=W19),AD19,IF(AND($L20=AD$4,P20=1),P20,0)))) -> 1 | AE20: =IF(AD20>1,AD20,IF(AND($P20>1,AE$4=$L20),$P20,IF(AND($U20=$U19,X20=X19),AE19,IF(AND($L20=AE$4,P20=1),P20,0)))) -> 0 | AF20: =IF(AE20>1,AE20,IF(AND($P20>1,AF$4=$L20),$P20,IF(AND($U20=$U19,Y20=Y19),AF19,IF(AND($L20=AF$4,P20=1),P20,0)))) -> 0 | AG20: =IF(AF20>1,AF20,IF(AND($P20>1,AG$4=$L20),$P20,IF(AND($U20=$U19,Z20=Z19),AG19,IF(AND($L20=AG$4,P20=1),P20,0)))) -> 0 | AH20: =IF(AND($P20=1,$L20=AH$4),2,IF(AND($L20<>AH$4,AH19=2),AH19,IF($L20<>AH$4,0,1))) -> 2 | AI20: =IF(OR(ROW()=5,$U19<>$U20),0,IF(AND($P20=1,$L20=AI$4),2,IF(AND($L20<>AI$4,AI19=2),AI19,IF($L20<>AI$4,0,1)))) -> 2 | AJ20: =IF(OR(ROW()=5,$U19<>$U20),0,IF(AND($P20=1,$L20=AJ$4),2,IF(AND($L20<>AJ$4,AJ19=2),AJ19,IF($L20<>AJ$4,0,1)))) -> 0 | AK20: =IF(OR(ROW()=5,$U19<>$U20),0,IF(AND($P20=1,$L20=AK$4),2,IF(AND($L20<>AK$4,AK19=2),AK19,IF($L20<>AK$4,0,1)))) -> 0 | AL20: =IF(OR(ROW()=5,$U19<>$U20),0,IF(AND($P20=1,$L20=AL$4),2,IF(AND($L20<>AL$4,AL19=2),AL19,IF($L20<>AL$4,0,1)))) -> 0
A21: 4640 | B21: A.3 | C21: Is there a formalized Risk Assessment process that identifies, quantifies, and prioritizes risks based on the risk acceptance levels relevant to the organization? | D21: Yes | G21: Enterprise Risk Management | H21: Risk Assessments | I21: A.4 IT Risk Assessments | J21: 6.1.2 Information Security Risk Asssessment|8.2 Information Security Risk Assessment | L21: 1 | M21: 2 | P21: =IF($L21="","",IF($D21="Yes",1,IF($D21="No",2,IF($D21="N/A",3,0)))) -> 1 | Q21: =IF(AND(Drops!$D$45>1,OR(U21<>U20,AND(ROW()=5,U20=U21))),VLOOKUP(U21,Drops!$D$26:$E$44,2,FALSE),"") | R21: =IF(Q21<>"",ROW(),"") | S21: =OFFSET(AC21,,L21-1) -> 1 | T21: =IF(OR(V21<>V20,U21<>U20,AND(V21<>V20,W21<>W20),AND(V21<>V20,W21<>W20,X21<>X20),AND(V21<>V20,W21<>W20,X21<>X20,Y21<>Y20),AND(V21<>V20,W21<>W20,X21<>X20,Y21<>Y20,Z21<>Z20),L21-L20>1),1,0) -> 1 | U21: A | V21: 3 | W21: 0 | X21: 0 | Y21: 0 | Z21: 0 | AA21: =IF(ROW()=5,1,IF(OR(AH21=1,P21>0,T21=1),1,IF(OR(AND(AH21=2,AI21=1),AND(AI21=2,AJ21=1),AND(AJ21=2,AK21=1),AND(AK21=2,AL21=1)),1,0))) -> 1 | AB21: =IF(L22>L21,1,0) -> 1 | AC21: =IF(ROW()=5,P21,IF(AND($P21>1,AC$4=$L21),$P21,IF(AND($U21=$U20,V21=V20),AC20,IF(AND($L21=AC$4,P21=1),P21,0)))) -> 1 | AD21: =IF(AC21>1,AC21,IF(AND($P21>1,AD$4=$L21),$P21,IF(AND($U21=$U20,W21=W20),AD20,IF(AND($L21=AD$4,P21=1),P21,0)))) -> 0 | AE21: =IF(AD21>1,AD21,IF(AND($P21>1,AE$4=$L21),$P21,IF(AND($U21=$U20,X21=X20),AE20,IF(AND($L21=AE$4,P21=1),P21,0)))) -> 0 | AF21: =IF(AE21>1,AE21,IF(AND($P21>1,AF$4=$L21),$P21,IF(AND($U21=$U20,Y21=Y20),AF20,IF(AND($L21=AF$4,P21=1),P21,0)))) -> 0 | AG21: =IF(AF21>1,AF21,IF(AND($P21>1,AG$4=$L21),$P21,IF(AND($U21=$U20,Z21=Z20),AG20,IF(AND($L21=AG$4,P21=1),P21,0)))) -> 0 | AH21: =IF(AND($P21=1,$L21=AH$4),2,IF(AND($L21<>AH$4,AH20=2),AH20,IF($L21<>AH$4,0,1))) -> 2 | AI21: =IF(OR(ROW()=5,$U20<>$U21),0,IF(AND($P21=1,$L21=AI$4),2,IF(AND($L21<>AI$4,AI20=2),AI20,IF($L21<>AI$4,0,1)))) -> 2 | AJ21: =IF(OR(ROW()=5,$U20<>$U21),0,IF(AND($P21=1,$L21=AJ$4),2,IF(AND($L21<>AJ$4,AJ20=2),AJ20,IF($L21<>AJ$4,0,1)))) -> 0 | AK21: =IF(OR(ROW()=5,$U20<>$U21),0,IF(AND($P21=1,$L21=AK$4),2,IF(AND($L21<>AK$4,AK20=2),AK20,IF($L21<>AK$4,0,1)))) -> 0 | AL21: =IF(OR(ROW()=5,$U20<>$U21),0,IF(AND($P21=1,$L21=AL$4),2,IF(AND($L21<>AL$4,AL20=2),AL20,IF($L21<>AL$4,0,1)))) -> 0
